<?xml version="1.0" encoding="utf-8"?>
<!-- This URDF was automatically created by SolidWorks to URDF Exporter! Originally created by Stephen Brawner (brawner@gmail.com) 
     Commit Version: 1.6.0-4-g7f85cfe  Build Version: 1.6.7995.38578
     For more information, please see http://wiki.ros.org/sw_urdf_exporter -->
<robot
  name="ABOT_V1.SLDASM">
  <link
    name="abot_base">
    <inertial>
      <origin
        xyz="-0.0183443466313837 0.0047848319676371 0.0529320262811739"
        rpy="0 0 0" />
      <mass
        value="0.596661013055953" />
      <inertia
        ixx="0.000637503890610936"
        ixy="-1.71156032169163E-06"
        ixz="-1.10441019829435E-05"
        iyy="0.000654924075366587"
        iyz="-8.13604595521774E-09"
        izz="0.00115018629675728" />
    </inertial>
    <visual>
      <origin
        xyz="0 0 0"
        rpy="0 0 0" />
      <geometry>
        <mesh
          filename="package://ABOT_V1.SLDASM/meshes/abot_base.STL" />
      </geometry>
      <material
        name="">
        <color
          rgba="0.752941176470588 0.752941176470588 0.752941176470588 1" />
      </material>
    </visual>
    <collision>
      <origin
        xyz="0 0 0"
        rpy="0 0 0" />
      <geometry>
        <mesh
          filename="package://ABOT_V1.SLDASM/meshes/abot_base.STL" />
      </geometry>
    </collision>
  </link>
  <link
    name="abot_left_wheel">
    <inertial>
      <origin
        xyz="-3.282E-11 0.00056576 -9.8272E-11"
        rpy="0 0 0" />
      <mass
        value="0.050464" />
      <inertia
        ixx="2.0701E-05"
        ixy="-3.837E-15"
        ixz="1.6309E-14"
        iyy="3.5827E-05"
        iyz="1.8547E-15"
        izz="2.0701E-05" />
    </inertial>
    <visual>
      <origin
        xyz="0 0 0"
        rpy="0 0 0" />
      <geometry>
        <mesh
          filename="package://ABOT_V1.SLDASM/meshes/abot_left_wheel.STL" />
      </geometry>
      <material
        name="">
        <color
          rgba="1 1 0 1" />
      </material>
    </visual>
    <collision>
      <origin
        xyz="0 0 0"
        rpy="0 0 0" />
      <geometry>
        <mesh
          filename="package://ABOT_V1.SLDASM/meshes/abot_left_wheel.STL" />
      </geometry>
    </collision>
  </link>
  <joint
    name="left_wheel_to_base"
    type="continuous">
    <origin
      xyz="0 0.068 0.0145"
      rpy="0 0 0" />
    <parent
      link="abot_base" />
    <child
      link="abot_left_wheel" />
    <axis
      xyz="0 1 0" />
  </joint>
  <link
    name="abot_right_wheel">
    <inertial>
      <origin
        xyz="-3.282E-11 -0.00056576 9.8272E-11"
        rpy="0 0 0" />
      <mass
        value="0.050464" />
      <inertia
        ixx="2.0701E-05"
        ixy="3.837E-15"
        ixz="-1.6309E-14"
        iyy="3.5827E-05"
        iyz="1.8547E-15"
        izz="2.0701E-05" />
    </inertial>
    <visual>
      <origin
        xyz="0 0 0"
        rpy="0 0 0" />
      <geometry>
        <mesh
          filename="package://ABOT_V1.SLDASM/meshes/abot_right_wheel.STL" />
      </geometry>
      <material
        name="">
        <color
          rgba="1 1 0 1" />
      </material>
    </visual>
    <collision>
      <origin
        xyz="0 0 0"
        rpy="0 0 0" />
      <geometry>
        <mesh
          filename="package://ABOT_V1.SLDASM/meshes/abot_right_wheel.STL" />
      </geometry>
    </collision>
  </link>
  <joint
    name="right_wheel_to_base"
    type="continuous">
    <origin
      xyz="0 -0.068 0.0145"
      rpy="0 0 0" />
    <parent
      link="abot_base" />
    <child
      link="abot_right_wheel" />
    <axis
      xyz="0 1 0" />
  </joint>
  <link
    name="abot_caster_wheel">
    <inertial>
      <origin
        xyz="0 1.6073E-19 0"
        rpy="0 0 0" />
      <mass
        value="0.011207" />
      <inertia
        ixx="2.1965E-07"
        ixy="-1.5533E-55"
        ixz="-1.9776E-56"
        iyy="2.1965E-07"
        iyz="-2.2674E-40"
        izz="2.1965E-07" />
    </inertial>
    <visual>
      <origin
        xyz="0 0 0"
        rpy="0 0 0" />
      <geometry>
        <mesh
          filename="package://ABOT_V1.SLDASM/meshes/abot_caster_wheel.STL" />
      </geometry>
      <material
        name="">
        <color
          rgba="0.52941 0.54902 0.54902 1" />
      </material>
    </visual>
    <collision>
      <origin
        xyz="0 0 0"
        rpy="0 0 0" />
      <geometry>
        <mesh
          filename="package://ABOT_V1.SLDASM/meshes/abot_caster_wheel.STL" />
      </geometry>
    </collision>
  </link>
  <joint
    name="caster_wheel_to_base"
    type="fixed">
    <origin
      xyz="-0.078 0 -0.011"
      rpy="0 0 0" />
    <parent
      link="abot_base" />
    <child
      link="abot_caster_wheel" />
    <axis
      xyz="0 0 0" />
  </joint>
  <link
    name="abot_lidar">
    <inertial>
      <origin
        xyz="0 0 0"
        rpy="0 0 0" />
      <mass
        value="0" />
      <inertia
        ixx="0"
        ixy="0"
        ixz="0"
        iyy="0"
        iyz="0"
        izz="0" />
    </inertial>
    <visual>
      <origin
        xyz="0 0 0"
        rpy="0 0 0" />
      <geometry>
        <mesh
          filename="package://ABOT_V1.SLDASM/meshes/abot_lidar.STL" />
      </geometry>
      <material
        name="">
        <color
          rgba="1 1 1 1" />
      </material>
    </visual>
    <collision>
      <origin
        xyz="0 0 0"
        rpy="0 0 0" />
      <geometry>
        <mesh
          filename="package://ABOT_V1.SLDASM/meshes/abot_lidar.STL" />
      </geometry>
    </collision>
  </link>
  <joint
    name="lidar_to_base"
    type="fixed">
    <origin
      xyz="-0.0100000000000004 0 0.1419"
      rpy="0 0 3.14159265358978" />
    <parent
      link="abot_base" />
    <child
      link="abot_lidar" />
    <axis
      xyz="0 0 0" />
  </joint>
</robot>